<robot
  name="0320_all_assembly">
  <link
    name="base_link">
    <inertial>
      <origin
        xyz="0.0850926657910792 -0.143434171023409 0.110709459123743"
        rpy="0 0 0" />
      <mass
        value="0.019899935517462" />
      <inertia
        ixx="1.88663880803478E-05"
        ixy="2.11655934416254E-06"
        ixz="4.15041155919205E-07"
        iyy="2.1804609783136E-06"
        iyz="-2.85101666775228E-06"
        izz="1.86626954662574E-05" />
    </inertial>
    <visual>
      <origin
        xyz="0 0 0"
        rpy="0 0 0" />
      <geometry>
        <mesh
          filename="package://0320_all_assembly/meshes/base_link.STL" />
      </geometry>
      <material
        name="">
        <color
          rgba="0.792156862745098 0.819607843137255 0.933333333333333 1" />
      </material>
    </visual>
    <collision>
      <origin
        xyz="0 0 0"
        rpy="0 0 0" />
      <geometry>
        <mesh
          filename="package://0320_all_assembly/meshes/base_link.STL" />
      </geometry>
    </collision>
  </link>
  <link
    name="link01">
    <inertial>
      <origin
        xyz="-0.0200421073686721 0.0152861157242461 -0.0465797264376506"
        rpy="0 0 0" />
      <mass
        value="0.019899935517462" />
      <inertia
        ixx="1.88663880803479E-05"
        ixy="4.15041155919206E-07"
        ixz="-2.11655934416255E-06"
        iyy="1.86626954662575E-05"
        iyz="2.85101666775228E-06"
        izz="2.1804609783136E-06" />
    </inertial>
    <visual>
      <origin
        xyz="0 0 0"
        rpy="0 0 0" />
      <geometry>
        <mesh
          filename="package://0320_all_assembly/meshes/link01.STL" />
      </geometry>
      <material
        name="">
        <color
          rgba="0.792156862745098 0.819607843137255 0.933333333333333 1" />
      </material>
    </visual>
    <collision>
      <origin
        xyz="0 0 0"
        rpy="0 0 0" />
      <geometry>
        <mesh
          filename="package://0320_all_assembly/meshes/link01.STL" />
      </geometry>
    </collision>
  </link>
  <joint
    name="joint01"
    type="revolute">
    <origin
      xyz="0.049254 -0.11831 0.11717"
      rpy="1.5555 -3.4699E-14 -3.1416" />
    <parent
      link="base_link" />
    <child
      link="link01" />
    <axis
      xyz="1 0 0" />
    <limit
      lower="0"
      upper="3.14"
      effort="0"
      velocity="0" />
  </joint>
  <link
    name="link02">
    <inertial>
      <origin
        xyz="-0.00856875783176665 -0.00806117546355672 -0.0096805147039927"
        rpy="0 0 0" />
      <mass
        value="0.00625564379675455" />
      <inertia
        ixx="1.26026701897412E-06"
        ixy="7.10216697853827E-08"
        ixz="1.30374282427878E-07"
        iyy="1.17452756198058E-06"
        iyz="-9.94146108547727E-08"
        izz="3.17482320639255E-07" />
    </inertial>
    <visual>
      <origin
        xyz="0 0 0"
        rpy="0 0 0" />
      <geometry>
        <mesh
          filename="package://0320_all_assembly/meshes/link02.STL" />
      </geometry>
      <material
        name="">
        <color
          rgba="0.792156862745098 0.819607843137255 0.933333333333333 1" />
      </material>
    </visual>
    <collision>
      <origin
        xyz="0 0 0"
        rpy="0 0 0" />
      <geometry>
        <mesh
          filename="package://0320_all_assembly/meshes/link02.STL" />
      </geometry>
    </collision>
  </link>
  <joint
    name="joint02"
    type="revolute">
    <origin
      xyz="-0.03188 0.02175 -0.0717"
      rpy="-3.1263 6.3716E-16 -4.1633E-14" />
    <parent
      link="link01" />
    <child
      link="link02" />
    <axis
      xyz="-1 0 0" />
    <limit
      lower="0"
      upper="3.14"
      effort="0"
      velocity="0" />
  </joint>
</robot>